<?xml version="1.0" encoding="utf-8"?>
<!-- This URDF was automatically created by SolidWorks to URDF Exporter! Originally created by Stephen Brawner (brawner@gmail.com) 
     Commit Version: 1.6.0-4-g7f85cfe  Build Version: 1.6.7995.38578
     For more information, please see http://wiki.ros.org/sw_urdf_exporter -->
<robot
  name="arm_description">
  <link
    name="Link_0">
    <inertial>
      <origin
        xyz="-0.0215700285371962 0.0191913255550109 0.149338413913734"
        rpy="0 0 0" />
      <mass
        value="0.495433467186066" />
      <inertia
        ixx="0.000495906716184892"
        ixy="-4.5890108110774E-07"
        ixz="1.52556399654665E-06"
        iyy="0.000501844781324666"
        iyz="2.89945495803764E-06"
        izz="0.000976550806599686" />
    </inertial>
    <visual>
      <origin
        xyz="0 0 0"
        rpy="0 0 0" />
      <geometry>
        <mesh
          filename="package://Xlerobot_arm_description/meshes/Link_0.STL" />
      </geometry>
      <material
        name="">
        <color
          rgba="0.752941176470588 0.752941176470588 0.752941176470588 1" />
      </material>
    </visual>
    <collision>
      <origin
        xyz="0 0 0"
        rpy="0 0 0" />
      <geometry>
        <mesh
          filename="package://Xlerobot_arm_description/meshes/Link_0.STL" />
      </geometry>
    </collision>
  </link>
  <link
    name="Link_1">
    <inertial>
      <origin
        xyz="0.00233303517128809 -0.000201203457518027 0.0161836921336685"
        rpy="0 0 0" />
      <mass
        value="0.115096221710961" />
      <inertia
        ixx="9.2475047401558E-05"
        ixy="6.06862842563457E-07"
        ixz="-8.33731746565458E-06"
        iyy="4.00015143451019E-05"
        iyz="-1.07377312506746E-06"
        izz="8.44544443178301E-05" />
    </inertial>
    <visual>
      <origin
        xyz="0 0 0"
        rpy="0 0 0" />
      <geometry>
        <mesh
          filename="package://Xlerobot_arm_description/meshes/Link_1.STL" />
      </geometry>
      <material
        name="">
        <color
          rgba="0.752941176470588 0.752941176470588 0.752941176470588 1" />
      </material>
    </visual>
    <collision>
      <origin
        xyz="0 0 0"
        rpy="0 0 0" />
      <geometry>
        <mesh
          filename="package://Xlerobot_arm_description/meshes/Link_1.STL" />
      </geometry>
    </collision>
  </link>
  <joint
    name="Joint_1"
    type="revolute">
    <origin
      xyz="-0.0214142437132751 0.0194456602348006 0.191605452072183"
      rpy="0.00211481861111635 0.0055702541140081 1.57079739593879" />
    <parent
      link="Link_0" />
    <child
      link="Link_1" />
    <axis
      xyz="0 0 1" />  <!-- Flipped to match motor direction -->
    <limit
      lower="-3.14"
      upper="3.14"
      effort="1"
      velocity="100" />
  </joint>
  <link
    name="Link_2">
    <inertial>
      <origin
        xyz="0.0780570375422681 -0.0088674340622745 0.0240329186177445"
        rpy="0 0 0" />
      <mass
        value="0.338617438506798" />
      <inertia
        ixx="0.000114901331593358"
        ixy="1.20877544725111E-08"
        ixz="-3.20258985447469E-10"
        iyy="0.000610112240999527"
        iyz="3.79821041697316E-08"
        izz="0.000585938107041635" />
    </inertial>
    <visual>
      <origin
        xyz="0 0 0"
        rpy="0 0 0" />
      <geometry>
        <mesh
          filename="package://Xlerobot_arm_description/meshes/Link_2.STL" />
      </geometry>
      <material
        name="">
        <color
          rgba="0.752941176470588 0.752941176470588 0.752941176470588 1" />
      </material>
    </visual>
    <collision>
      <origin
        xyz="0 0 0"
        rpy="0 0 0" />
      <geometry>
        <mesh
          filename="package://Xlerobot_arm_description/meshes/Link_2.STL" />
      </geometry>
    </collision>
  </link>
  <joint
    name="Joint_2"
    type="revolute">
    <origin
      xyz="0.0127389581992879 -0.0251499999999623 0.0402999999999978"
      rpy="1.5707963267949 -0.144346094516988 -3.14159265358979" />
    <parent
      link="Link_1" />
    <child
      link="Link_2" />
    <axis
      xyz="0 0 1" />
    <limit
      lower="-3.14"
      upper="3.14"
      effort="1"
      velocity="100" />
  </joint>
  <link
    name="Link_3">
    <inertial>
      <origin
        xyz="0.0735490465153241 -0.0193684939862219 0.0260291733220808"
        rpy="0 0 0" />
      <mass
        value="0.262127893857478" />
      <inertia
        ixx="0.000116813910307825"
        ixy="2.84719134959355E-05"
        ixz="2.39642278489291E-06"
        iyy="0.000466008659281839"
        iyz="-8.38356086492127E-07"
        izz="0.000418021555796299" />
    </inertial>
    <visual>
      <origin
        xyz="0 0 0"
        rpy="0 0 0" />
      <geometry>
        <mesh
          filename="package://Xlerobot_arm_description/meshes/Link_3.STL" />
      </geometry>
      <material
        name="">
        <color
          rgba="0.752941176470588 0.752941176470588 0.752941176470588 1" />
      </material>
    </visual>
    <collision>
      <origin
        xyz="0 0 0"
        rpy="0 0 0" />
      <geometry>
        <mesh
          filename="package://Xlerobot_arm_description/meshes/Link_3.STL" />
      </geometry>
    </collision>
  </link>
  <joint
    name="Joint_3"
    type="revolute">
    <origin
      xyz="0.160000000000267 0 -0.00229999999998206"
      rpy="0 0 3.00260429580537" />
    <parent
      link="Link_2" />
    <child
      link="Link_3" />
    <axis
      xyz="0 0 -1" />  <!-- Flipped to match motor direction -->
    <limit
      lower="-3.14"
      upper="3.14"
      effort="1"
      velocity="100" />
  </joint>
  <link
    name="Link_4">
    <inertial>
      <origin
        xyz="0.0290324812561034 0.0308275832255656 -0.0302284308768422"
        rpy="0 0 0" />
      <mass
        value="0.183550046357377" />
      <inertia
        ixx="9.80608942798305E-05"
        ixy="-1.25256496775757E-05"
        ixz="-8.62417276991685E-07"
        iyy="0.000109351384724414"
        iyz="-1.05207766478973E-06"
        izz="5.28926596761056E-05" />
    </inertial>
    <visual>
      <origin
        xyz="0 0 0"
        rpy="0 0 0" />
      <geometry>
        <mesh
          filename="package://Xlerobot_arm_description/meshes/Link_4.STL" />
      </geometry>
      <material
        name="">
        <color
          rgba="0.752941176470588 0.752941176470588 0.752941176470588 1" />
      </material>
    </visual>
    <collision>
      <origin
        xyz="0 0 0"
        rpy="0 0 0" />
      <geometry>
        <mesh
          filename="package://Xlerobot_arm_description/meshes/Link_4.STL" />
      </geometry>
    </collision>
  </link>
  <joint
    name="Joint_4"
    type="revolute">
    <origin
      xyz="0.138999999999995 -0.022500000000037 -0.00365397222864563"
      rpy="3.14159265358979 0 0" />
    <parent
      link="Link_3" />
    <child
      link="Link_4" />
    <axis
      xyz="0 0 1" />  <!-- Flipped to match motor direction -->
    <limit
      lower="-3.14"
      upper="3.14"
      effort="1"
      velocity="100" />
  </joint>
  <link
    name="Link_5">
    <inertial>
      <origin
        xyz="0.00361332956404915 -3.44973423708796E-05 0.01478189501244"
        rpy="0 0 0" />
      <mass
        value="0.109318647061635" />
      <inertia
        ixx="2.73308194890512E-05"
        ixy="-2.01511172174708E-09"
        ixz="-8.81881130818584E-07"
        iyy="2.66620658675184E-05"
        iyz="-7.70299323219792E-08"
        izz="3.74347009989327E-05" />
    </inertial>
    <visual>
      <origin
        xyz="0 0 0"
        rpy="0 0 0" />
      <geometry>
        <mesh
          filename="package://Xlerobot_arm_description/meshes/Link_5.STL" />
      </geometry>
      <material
        name="">
        <color
          rgba="0.752941176470588 0.752941176470588 0.752941176470588 1" />
      </material>
    </visual>
    <collision>
      <origin
        xyz="0 0 0"
        rpy="0 0 0" />
      <geometry>
        <mesh
          filename="package://Xlerobot_arm_description/meshes/Link_5.STL" />
      </geometry>
    </collision>
  </link>
  <joint
    name="Joint_5"
    type="revolute">
    <origin
      xyz="0.058078218985555 0.0302999999999997 -0.0304500000000002"
      rpy="1.57079632679489 0 0" />
    <parent
      link="Link_4" />
    <child
      link="Link_5" />
    <axis
      xyz="0 0 1" />  <!-- Reverted - original was correct -->
    <limit
      lower="-3.14"
      upper="3.14"
      effort="1"
      velocity="100" />
  </joint>
  <link
    name="Link_6">
    <inertial>
      <origin
        xyz="0.000111798786011107 -3.04064623025679E-05 0.0381722986137639"
        rpy="0 0 0" />
      <mass
        value="0.0597934624600572" />
      <inertia
        ixx="6.9704282069037E-06"
        ixy="-2.16746441308965E-08"
        ixz="1.82459809303624E-08"
        iyy="3.794441586587E-05"
        iyz="1.19423849004993E-09"
        izz="4.19303939961101E-05" />
    </inertial>
    <visual>
      <origin
        xyz="0 0 0"
        rpy="0 0 0" />
      <geometry>
        <mesh
          filename="package://Xlerobot_arm_description/meshes/Link_6.STL" />
      </geometry>
      <material
        name="">
        <color
          rgba="0.752941176470588 0.752941176470588 0.752941176470588 1" />
      </material>
    </visual>
    <collision>
      <origin
        xyz="0 0 0"
        rpy="0 0 0" />
      <geometry>
        <mesh
          filename="package://Xlerobot_arm_description/meshes/Link_6.STL" />
      </geometry>
    </collision>
  </link>
  <joint
    name="Joint_6"
    type="revolute">
    <origin
      xyz="0.0235000000000267 0 0.0302999999999897"
      rpy="-1.5707963267949 0 -1.5707963267949" />
    <parent
      link="Link_5" />
    <child
      link="Link_6" />
    <axis
      xyz="0 0 1" />
    <limit
      lower="-3.14"
      upper="3.14"
      effort="1"
      velocity="100" />
  </joint>
</robot>